//this is an auto-generated bug report
//package name: com.adonai.manman
//version: 1.5.2
//appro_time: 31
 java.lang.RuntimeException: An error occurred while executing doInBackground()
 	at android.support.v4.c.w.done(Unknown Source)
 	at java.util.concurrent.FutureTask.finishCompletion(FutureTask.java:352)
 	at java.util.concurrent.FutureTask.setException(FutureTask.java:219)
 	at java.util.concurrent.FutureTask.run(FutureTask.java:239)
 	at java.util.concurrent.ThreadPoolExecutor.runWorker(ThreadPoolExecutor.java:1080)
 	at java.util.concurrent.ThreadPoolExecutor$Worker.run(ThreadPoolExecutor.java:573)
 	at java.lang.Thread.run(Thread.java:841)
 Caused by: java.lang.NullPointerException
 	at com.adonai.manman.ManChaptersFragment$RetrieveContentsCallback$1.loadInBackground(Unknown Source)
 	at com.adonai.manman.ManChaptersFragment$RetrieveContentsCallback$1.loadInBackground(Unknown Source)
 	at com.adonai.manman.misc.AbstractNetworkAsyncLoader.onLoadInBackground(Unknown Source)
 	at android.support.v4.c.b.a(Unknown Source)
 	at android.support.v4.c.b.a(Unknown Source)
 	at android.support.v4.c.v.call(Unknown Source)
 	at java.util.concurrent.FutureTask.run(FutureTask.java:234)
